Workbook
Name c_country: Analysis!$C$6
Name c_from: Analysis!$C$8
Name c_genre: Analysis!$C$7
Name c_rg: Analysis!$C$5
Name c_to: Analysis!$C$9
Name c_type: Analysis!$C$4
Name d_all: Data!$A$2:$A$8808
Name d_cast: Data!$U$2:$U$8808
Name d_ctry: Data!$R$2:$R$8808
Name d_dirk: Data!$T$2:$T$8808
Name d_dv: Data!$P$2:$P$8808
Name d_genre: Data!$S$2:$S$8808
Name d_mo: Data!$N$2:$N$8808
Name d_pc: Data!$Q$2:$Q$8808
Name d_rating: Data!$I$2:$I$8808
Name d_rg: Data!$O$2:$O$8808
Name d_ry: Data!$H$2:$H$8808
Name d_title: Data!$C$2:$C$8808
Name d_type: Data!$B$2:$B$8808
Name d_ya: Data!$M$2:$M$8808
Name list_country: Lists!$C$2:$C$125
Name list_genre: Lists!$D$2:$D$44
Name list_rg: Lists!$B$2:$B$7
Name list_type: Lists!$A$2:$A$4
Name list_year: Lists!$E$2:$E$98

Sheet About (2)
B1: PROJECT GUIDE & DOCUMENTATION
B2: ← Back to Dashboard
B5: PROJECT DETAILS (edit the highlighted cells)
B6: Project title | C6: Netflix Content Analytics – Interactive Excel Dashboard
B7: Prepared by | C7: [Your Name]
B8: Enrollment / Roll No. | C8: [Roll Number]
B9: Course / Department | C9: [Course – Final Year]
B10: Guide / Supervisor | C10: [Guide Name]
B11: Academic year | C11: [20XX – 20XX]
B13: OBJECTIVE
B14: Aim | C14: To analyse Netflix's catalogue of Movies and TV Shows – what is available, where it comes from, who it is made for and how it has grown – using an interactive Excel dashboard.
B15: Dataset | C15: netflix_titles.csv – 8,807 titles × 12 columns (type, title, director, cast, country, date added, release year, rating, duration, genres, description).
B17: HOW TO USE THE DASHBOARD
B18: 1. Filters | C18: On the Dashboard use the six drop-downs (Type, Audience, Country, Genre, Release-year from / to). Every KPI, chart and insight updates instantly.
B19: 2. Reset | C19: Set Type / Audience / Country / Genre back to 'All' and the years to 1925 – 2021.
B20: 3. Title Explorer | C20: Look up any title for full details, or press F9 on that sheet for a random pick.
B21: 4. Navigation | C21: Use the links in the Dashboard header to jump between sheets.
B23: SHEETS
B24: Dashboard | C24: Presentation layer – filters, 6 KPI cards, 11 charts and auto-generated insights.
B25: Title Explorer | C25: Search-by-title card built with MATCH / INDEX, plus a random-title generator.
B26: Analysis | C26: Calculation engine – all summary tables (COUNTIFS) that feed the charts; includes Top-10 ranking tables.
B27: Data | C27: Cleaned dataset + 9 helper columns (red headers) built with formulas.
B28: Lists | C28: Source lists for drop-downs and the rating → audience-group mapping table.
B30: EXCEL TECHNIQUES USED
B31: Formulas | C31: COUNTIFS (multi-criteria with wildcards), AVERAGEIFS, INDEX / MATCH, LARGE, VLOOKUP, SUBSTITUTE, TEXT, IFERROR, RANDBETWEEN, YEAR, MONTH
B32: Named ranges | C32: Data columns (d_type, d_ry, d_genre …) and filter criteria (c_type, c_from …) keep formulas short and readable
B33: Dynamic Top-10 | C33: Score column with a row-based tie-breaker + LARGE / MATCH → live-ranked tables without dynamic-array functions (works in every Excel version)
B34: Multi-value fields | C34: Country, genre, director and cast are pipe-delimited ('|Drama|Comedy|') in helper columns so a title counts once for EACH country / genre / person
B35: Data validation | C35: Drop-down filters (named lists) and the title search box
B36: Conditional formatting | C36: Active filters turn pink; data-bars on ranking tables
B37: Charts | C37: Line, doughnut, column and bar charts linked to formula ranges, so they react to the filters
B38: Navigation & printing | C38: Internal hyperlinks, frozen filter bar, landscape fit-to-width print setup
B40: DATA CLEANING STEPS
B41: Missing director / cast / country | C41: Replaced blanks with 'Unknown' (director 2,634; cast 825; country 831 records).
B42: Date added | C42: Text such as 'September 25, 2021' converted to real Excel dates (10 records have no date and are excluded from year/month charts only).
B43: Rating column errors | C43: 3 records had runtime values (e.g. '74 min') in the rating field – moved to duration, rating set to 'Not Rated'; 4 blank ratings also set to 'Not Rated'.
B44: Rating groups | C44: Kids (TV-Y, TV-Y7, TV-G, G) · Older Kids (TV-PG, PG) · Teens (TV-14, PG-13) · Adults (TV-MA, R, NC-17) · Not Rated (NR, UR). Editable in Lists!F:G.
B45: Whitespace | C45: Leading / trailing spaces and stray commas trimmed from text fields.
B47: NOTES & LIMITATIONS
B48: Directors / actors | C48: Ranked from the 30 most frequent directors and 40 most frequent actors in the full dataset (counting every name across all rows would need dynamic arrays); the Top-10 shown is live-ranked within those candidates.
...

Sheet DASHBOARD
B1: NETFLIX CONTENT ANALYTICS DASHBOARD
B2: Interactive insights on 8,800+ Movies & TV Shows | use the filters below to slice every KPI and chart | R2: Title Explorer | T2: Analysis | V2: Data | X2: About
B4: ▼ TYPE | F4: ▼ AUDIENCE (RATING GROUP) | J4: ▼ COUNTRY | N4: ▼ GENRE | R4: ▼ RELEASE YEAR FROM | V4: ▼ RELEASE YEAR TO
B5: Movie | F5: Teens | J5: India | N5: Action & Adventure | R5: 1925 | V5: 2017
B8: TOTAL TITLES | F8: MOVIES | J8: TV SHOWS | N8: COUNTRIES | R8: AVG MOVIE LENGTH | V8: AVG TV SEASONS
B9: =Analysis!$C$15 -> 92 | F9: =Analysis!$C$13 -> 92 | J9: =Analysis!$C$14 -> 0 | N9: =COUNTIFS(Analysis!$C$104:$C$226,">0",Analysis!$B$104:$B$226,"<>Unknown") -> 5 | R9: =Analysis!$C$96 -> 144 | V9: =Analysis!$C$97 -> n/a
B11: =TEXT($R$5,"0")&" – "&TEXT($V$5,"0")&" releases" -> 1925 – 2017 releases | F11: =TEXT(Analysis!$D$13,"0.0%")&" of view" -> 100.0% of view | J11: =TEXT(Analysis!$D$14,"0.0%")&" of view" -> 0.0% of view | N11: =IF(Analysis!$B$230="","–","Top: "&Analysis!$B$230) -> Top: India | R11: ="minutes per movie" -> minutes per movie | V11: ="seasons per show" -> seasons per show
B13: TRENDS & MIX
B29: GEOGRAPHY, GENRE & RELEASE ERA
B46: WHEN & HOW LONG
B63: TALENT SPOTLIGHT

Sheet Title Explorer
B1: TITLE EXPLORER | Z1: =IFERROR(MATCH($B$6,d_title,0),0) -> 3686
B2: ← Back to Dashboard
B5: ▼ PICK OR TYPE A TITLE (exact name, any letter case) — click the cell, then the arrow
B6: Stranger Things
B7: =IF(ISNUMBER(MATCH($B$6,d_title,0)),"✔ Match found","✖ Title not found – check spelling or pick from the dropdown") -> ✔ Match found
B9: Title | C9: =IF($Z$1=0,"–",INDEX(Data!$C$2:$C$8808,$Z$1)) -> Stranger Things
B10: Type | C10: =IF($Z$1=0,"–",INDEX(Data!$B$2:$B$8808,$Z$1)) -> TV Show
B11: Release year | C11: =IF($Z$1=0,"–",INDEX(Data!$H$2:$H$8808,$Z$1)) -> 2019
B12: Added to Netflix | C12: =IF($Z$1=0,"–",IF(INDEX(Data!$G$2:$G$8808,$Z$1)="","Unknown",INDEX(Data!$G$2:$G$8808,$Z$1))) -> 43650
B13: Rating | C13: =IF($Z$1=0,"–",INDEX(Data!$I$2:$I$8808,$Z$1)) -> TV-14
B14: Audience group | C14: =IF($Z$1=0,"–",INDEX(Data!$O$2:$O$8808,$Z$1)) -> Teens
B15: Duration | C15: =IF($Z$1=0,"–",INDEX(Data!$J$2:$J$8808,$Z$1)) -> 3 Seasons
B16: Country | C16: =IF($Z$1=0,"–",INDEX(Data!$F$2:$F$8808,$Z$1)) -> United States
B17: Director | C17: =IF($Z$1=0,"–",INDEX(Data!$D$2:$D$8808,$Z$1)) -> Unknown
B18: Cast | C18: =IF($Z$1=0,"–",INDEX(Data!$E$2:$E$8808,$Z$1)) -> Winona Ryder, David Harbour, Finn Wolfhard, Millie Bobby Brown, Gaten Matarazzo, Caleb McLaughlin, Natalia Dyer, Charlie Heaton, Cara Buono, Noah Schnapp, Matthew Modine, Joe Keery, Dacre Montgomery, Sadie Sink, Paul Reiser, Sean Astin
B19: Genres | C19: =IF($Z$1=0,"–",INDEX(Data!$K$2:$K$8808,$Z$1)) -> TV Horror, TV Mysteries, TV Sci-Fi & Fantasy
B20: Description | C20: =IF($Z$1=0,"–",INDEX(Data!$L$2:$L$8808,$Z$1)) -> When a young boy vanishes, a small town uncovers a mystery involving secret experiments, terrifying supernatural forces and one strange little girl.

Sheet Analysis
B1: ANALYSIS ENGINE | every table recalculates from the Dashboard filters
B2: ← Back to Dashboard
B3: FILTER CRITERIA (read from Dashboard)
B4: Type | C4: =IF(DASHBOARD!$B$5="All","*",DASHBOARD!$B$5) -> Movie
B5: Rating group | C5: =IF(DASHBOARD!$F$5="All","*",DASHBOARD!$F$5) -> Teens
B6: Country (key) | C6: =IF(DASHBOARD!$J$5="All","*","*|"&DASHBOARD!$J$5&"|*") -> *|India|*
B7: Genre (key) | C7: =IF(DASHBOARD!$N$5="All","*","*|"&DASHBOARD!$N$5&"|*") -> *|Action & Adventure|*
B8: Release year ≥ | C8: =">="&DASHBOARD!$R$5 -> >=1925
B9: Release year ≤ | C9: ="<="&DASHBOARD!$V$5 -> <=2017
B11: 1 · CONTENT TYPE
B12: Type | C12: Titles | D12: Share
B13: Movie | C13: =COUNTIFS(d_type,c_type,d_rg,c_rg,d_ctry,c_country,d_genre,c_genre,d_ry,c_from,d_ry,c_to,d_type,"Movie") -> 92 | D13: =IFERROR(C13/SUM($C$13:$C$14),0) -> 1
B14: TV Show | C14: =COUNTIFS(d_type,c_type,d_rg,c_rg,d_ctry,c_country,d_genre,c_genre,d_ry,c_from,d_ry,c_to,d_type,"TV Show") -> 0 | D14: =IFERROR(C14/SUM($C$13:$C$14),0) -> 0
B15: Total (current view) | C15: =SUM(C13:C14) -> 92
B16: All titles (no filter) | C16: =COUNTA(d_all) -> 8807
B19: 2 · AUDIENCE / RATING GROUP
B20: Group | C20: Titles | D20: Share
B21: Adults | C21: =COUNTIFS(d_type,c_type,d_rg,c_rg,d_ctry,c_country,d_genre,c_genre,d_ry,c_from,d_ry,c_to,d_rg,"Adults") -> 0 | D21: =IFERROR(C21/SUM($C$21:$C$25),0) -> 0
B22: Teens | C22: =COUNTIFS(d_type,c_type,d_rg,c_rg,d_ctry,c_country,d_genre,c_genre,d_ry,c_from,d_ry,c_to,d_rg,"Teens") -> 92 | D22: =IFERROR(C22/SUM($C$21:$C$25),0) -> 1
B23: Older Kids | C23: =COUNTIFS(d_type,c_type,d_rg,c_rg,d_ctry,c_country,d_genre,c_genre,d_ry,c_from,d_ry,c_to,d_rg,"Older Kids") -> 0 | D23: =IFERROR(C23/SUM($C$21:$C$25),0) -> 0
B24: Kids | C24: =COUNTIFS(d_type,c_type,d_rg,c_rg,d_ctry,c_country,d_genre,c_genre,d_ry,c_from,d_ry,c_to,d_rg,"Kids") -> 0 | D24: =IFERROR(C24/SUM($C$21:$C$25),0) -> 0
B25: Not Rated | C25: =COUNTIFS(d_type,c_type,d_rg,c_rg,d_ctry,c_country,d_genre,c_genre,d_ry,c_from,d_ry,c_to,d_rg,"Not Rated") -> 0 | D25: =IFERROR(C25/SUM($C$21:$C$25),0) -> 0
B28: 3 · TITLES ADDED PER YEAR
B29: Year Added | C29: Movies | D29: TV Shows | E29: Total
B30: 2008 | C30: =COUNTIFS(d_type,c_type,d_rg,c_rg,d_ctry,c_country,d_genre,c_genre,d_ry,c_from,d_ry,c_to,d_ya,$B30,d_type,"Movie") -> 0 | D30: =COUNTIFS(d_type,c_type,d_rg,c_rg,d_ctry,c_country,d_genre,c_genre,d_ry,c_from,d_ry,c_to,d_ya,$B30,d_type,"TV Show") -> 0 | E30: =C30+D30 -> 0
B31: 2009 | C31: =COUNTIFS(d_type,c_type,d_rg,c_rg,d_ctry,c_country,d_genre,c_genre,d_ry,c_from,d_ry,c_to,d_ya,$B31,d_type,"Movie") -> 0 | D31: =COUNTIFS(d_type,c_type,d_rg,c_rg,d_ctry,c_country,d_genre,c_genre,d_ry,c_from,d_ry,c_to,d_ya,$B31,d_type,"TV Show") -> 0 | E31: =C31+D31 -> 0
B32: 2010 | C32: =COUNTIFS(d_type,c_type,d_rg,c_rg,d_ctry,c_country,d_genre,c_genre,d_ry,c_from,d_ry,c_to,d_ya,$B32,d_type,"Movie") -> 0 | D32: =COUNTIFS(d_type,c_type,d_rg,c_rg,d_ctry,c_country,d_genre,c_genre,d_ry,c_from,d_ry,c_to,d_ya,$B32,d_type,"TV Show") -> 0 | E32: =C32+D32 -> 0
B33: 2011 | C33: =COUNTIFS(d_type,c_type,d_rg,c_rg,d_ctry,c_country,d_genre,c_genre,d_ry,c_from,d_ry,c_to,d_ya,$B33,d_type,"Movie") -> 0 | D33: =COUNTIFS(d_type,c_type,d_rg,c_rg,d_ctry,c_country,d_genre,c_genre,d_ry,c_from,d_ry,c_to,d_ya,$B33,d_type,"TV Show") -> 0 | E33: =C33+D33 -> 0
B34: 2012 | C34: =COUNTIFS(d_type,c_type,d_rg,c_rg,d_ctry,c_country,d_genre,c_genre,d_ry,c_from,d_ry,c_to,d_ya,$B34,d_type,"Movie") -> 0 | D34: =COUNTIFS(d_type,c_type,d_rg,c_rg,d_ctry,c_country,d_genre,c_genre,d_ry,c_from,d_ry,c_to,d_ya,$B34,d_type,"TV Show") -> 0 | E34: =C34+D34 -> 0
B35: 2013 | C35: =COUNTIFS(d_type,c_type,d_rg,c_rg,d_ctry,c_country,d_genre,c_genre,d_ry,c_from,d_ry,c_to,d_ya,$B35,d_type,"Movie") -> 0 | D35: =COUNTIFS(d_type,c_type,d_rg,c_rg,d_ctry,c_country,d_genre,c_genre,d_ry,c_from,d_ry,c_to,d_ya,$B35,d_type,"TV Show") -> 0 | E35: =C35+D35 -> 0
B36: 2014 | C36: =COUNTIFS(d_type,c_type,d_rg,c_rg,d_ctry,c_country,d_genre,c_genre,d_ry,c_from,d_ry,c_to,d_ya,$B36,d_type,"Movie") -> 0 | D36: =COUNTIFS(d_type,c_type,d_rg,c_rg,d_ctry,c_country,d_genre,c_genre,d_ry,c_from,d_ry,c_to,d_ya,$B36,d_type,"TV Show") -> 0 | E36: =C36+D36 -> 0
B37: 2015 | C37: =COUNTIFS(d_type,c_type,d_rg,c_rg,d_ctry,c_country,d_genre,c_genre,d_ry,c_from,d_ry,c_to,d_ya,$B37,d_type,"Movie") -> 0 | D37: =COUNTIFS(d_type,c_type,d_rg,c_rg,d_ctry,c_country,d_genre,c_genre,d_ry,c_from,d_ry,c_to,d_ya,$B37,d_type,"TV Show") -> 0 | E37: =C37+D37 -> 0
B38: 2016 | C38: =COUNTIFS(d_type,c_type,d_rg,c_rg,d_ctry,c_country,d_genre,c_genre,d_ry,c_from,d_ry,c_to,d_ya,$B38,d_type,"Movie") -> 0 | D38: =COUNTIFS(d_type,c_type,d_rg,c_rg,d_ctry,c_country,d_genre,c_genre,d_ry,c_from,d_ry,c_to,d_ya,$B38,d_type,"TV Show") -> 0 | E38: =C38+D38 -> 0
B39: 2017 | C39: =COUNTIFS(d_type,c_type,d_rg,c_rg,d_ctry,c_country,d_genre,c_genre,d_ry,c_from,d_ry,c_to,d_ya,$B39,d_type,"Movie") -> 20 | D39: =COUNTIFS(d_type,c_type,d_rg,c_rg,d_ctry,c_country,d_genre,c_genre,d_ry,c_from,d_ry,c_to,d_ya,$B39,d_type,"TV Show") -> 0 | E39: =C39+D39 -> 20
B40: 2018 | C40: =COUNTIFS(d_type,c_type,d_rg,c_rg,d_ctry,c_country,d_genre,c_genre,d_ry,c_from,d_ry,c_to,d_ya,$B40,d_type,"Movie") -> 38 | D40: =COUNTIFS(d_type,c_type,d_rg,c_rg,d_ctry,c_country,d_genre,c_genre,d_ry,c_from,d_ry,c_to,d_ya,$B40,d_type,"TV Show") -> 0 | E40: =C40+D40 -> 38
B41: 2019 | C41: =COUNTIFS(d_type,c_type,d_rg,c_rg,d_ctry,c_country,d_genre,c_genre,d_ry,c_from,d_ry,c_to,d_ya,$B41,d_type,"Movie") -> 11 | D41: =COUNTIFS(d_type,c_type,d_rg,c_rg,d_ctry,c_country,d_genre,c_genre,d_ry,c_from,d_ry,c_to,d_ya,$B41,d_type,"TV Show") -> 0 | E41: =C41+D41 -> 11
... B43: 2021 | C43: =COUNTIFS(d_type,c_type,d_rg,c_rg,d_ctry,c_country,d_genre,c_genre,d_ry,c_from,d_ry,c_to,d_ya,$B43,d_type,"Movie") -> 7 | D43: =COUNTIFS(d_type,c_type,d_rg,c_rg,d_ctry,c_country,d_genre,c_genre,d_ry,c_from,d_ry,c_to,d_ya,$B43,d_type,"TV Show") -> 0 | E43: =C43+D43 -> 7
B46: 4 · TITLES BY RELEASE YEAR
B47: Label | C47: From | D47: To | E47: Titles
B48: <2010 | C48: 0 | D48: 2009 | E48: =COUNTIFS(d_type,c_type,d_rg,c_rg,d_ctry,c_country,d_genre,c_genre,d_ry,c_from,d_ry,c_to,d_ry,">="&C48,d_ry,"<="&D48) -> 37
...

Sheet Data
A1: show_id | B1: type | C1: title | D1: director | E1: cast | F1: country | G1: date_added | H1: release_year | I1: rating | J1: duration | K1: listed_in | L1: description | M1: Year Added | N1: Month Added | O1: Rating Group | P1: Duration Value | Q1: Primary Country | R1: Countries Key | S1: Genres Key | T1: Directors Key | U1: Cast Key
A2: s1 | B2: Movie | C2: Dick Johnson Is Dead | D2: Kirsten Johnson | E2: Unknown | F2: United States | G2: 44464 | H2: 2020 | I2: PG-13 | J2: 90 min | K2: Documentaries | L2: As her father nears the end of his life, filmmaker Kirsten Johnson stages his death in inventive and comical ways to help them both face the inevitable. | M2: =IF(G2="","",YEAR(G2)) -> 2021 | N2: =IF(G2="","",MONTH(G2)) -> 9 | O2: =IFERROR(VLOOKUP(I2,Lists!$F$2:$G$16,2,FALSE()),"Not Rated") -> Teens | P2: =IFERROR(VALUE(LEFT(J2,FIND(" ",J2)-1)),"") -> 90 | Q2: =IFERROR(LEFT(F2,FIND(",",F2)-1),F2) -> United States | R2: ="|"&SUBSTITUTE(F2,", ","|")&"|" -> |United States| | S2: ="|"&SUBSTITUTE(K2,", ","|")&"|" -> |Documentaries| | T2: ="|"&SUBSTITUTE(D2,", ","|")&"|" -> |Kirsten Johnson| | U2: ="|"&SUBSTITUTE(E2,", ","|")&"|" -> |Unknown|
A3: s2 | B3: TV Show | C3: Blood & Water | D3: Unknown | E3: Ama Qamata, Khosi Ngema, Gail Mabalane, Thabang Molaba, Dillon Windvogel, Natasha Thahane, Arno Greeff, Xolile Tshabalala, Getmore Sithole, Cindy Mahlangu, Ryle De Morny, Greteli Fincham, Sello Maake Ka-Ncube, Odwa Gwanya, Mekaila Mathys, Sandi Schultz, Duane Williams, Shamilla Miller, Patrick Mofokeng | F3: South Africa | G3: 44463 | H3: 2021 | I3: TV-MA | J3: 2 Seasons | K3: International TV Shows, TV Dramas, TV Mysteries | L3: After crossing paths at a party, a Cape Town teen sets out to prove whether a private-school swimming star is her sister who was abducted at birth. | M3: =IF(G3="","",YEAR(G3)) -> 2021 | N3: =IF(G3="","",MONTH(G3)) -> 9 | O3: =IFERROR(VLOOKUP(I3,Lists!$F$2:$G$16,2,FALSE()),"Not Rated") -> Adults | P3: =IFERROR(VALUE(LEFT(J3,FIND(" ",J3)-1)),"") -> 2 | Q3: =IFERROR(LEFT(F3,FIND(",",F3)-1),F3) -> South Africa | R3: ="|"&SUBSTITUTE(F3,", ","|")&"|" -> |South Africa| | S3: ="|"&SUBSTITUTE(K3,", ","|")&"|" -> |International TV Shows|TV Dramas|TV Mysteries| | T3: ="|"&SUBSTITUTE(D3,", ","|")&"|" -> |Unknown| | U3: ="|"&SUBSTITUTE(E3,", ","|")&"|" -> |Ama Qamata|Khosi Ngema|Gail Mabalane|Thabang Molaba|Dillon Windvogel|Natasha Thahane|Arno Greeff|Xolile Tshabalala|Getmore Sithole|Cindy Mahlangu|Ryle De Morny|Greteli Fincham|Sello Maake Ka-Ncube|Odwa Gwanya|Mekaila Mathys|Sandi Schultz|Duane Williams|Shamilla Miller|Patrick Mofokeng|
A4: s3 | B4: TV Show | C4: Ganglands | D4: Julien Leclercq | E4: Sami Bouajila, Tracy Gotoas, Samuel Jouy, Nabiha Akkari, Sofia Lesaffre, Salim Kechiouche, Noureddine Farihi, Geert Van Rampelberg, Bakary Diombera | F4: Unknown | G4: 44463 | H4: 2021 | I4: TV-MA | J4: 1 Season | K4: Crime TV Shows, International TV Shows, TV Action & Adventure | L4: To protect his family from a powerful drug lord, skilled thief Mehdi and his expert team of robbers are pulled into a violent and deadly turf war. | M4: =IF(G4="","",YEAR(G4)) -> 2021 | N4: =IF(G4="","",MONTH(G4)) -> 9 | O4: =IFERROR(VLOOKUP(I4,Lists!$F$2:$G$16,2,FALSE()),"Not Rated") -> Adults | P4: =IFERROR(VALUE(LEFT(J4,FIND(" ",J4)-1)),"") -> 1 | Q4: =IFERROR(LEFT(F4,FIND(",",F4)-1),F4) -> Unknown | R4: ="|"&SUBSTITUTE(F4,", ","|")&"|" -> |Unknown| | S4: ="|"&SUBSTITUTE(K4,", ","|")&"|" -> |Crime TV Shows|International TV Shows|TV Action & Adventure| | T4: ="|"&SUBSTITUTE(D4,", ","|")&"|" -> |Julien Leclercq| | U4: ="|"&SUBSTITUTE(E4,", ","|")&"|" -> |Sami Bouajila|Tracy Gotoas|Samuel Jouy|Nabiha Akkari|Sofia Lesaffre|Salim Kechiouche|Noureddine Farihi|Geert Van Rampelberg|Bakary Diombera|
A5: s4 | B5: TV Show | C5: Jailbirds New Orleans | D5: Unknown | E5: Unknown | F5: Unknown | G5: 44463 | H5: 2021 | I5: TV-MA | J5: 1 Season | K5: Docuseries, Reality TV | L5: Feuds, flirtations and toilet talk go down among the incarcerated women at the Orleans Justice Center in New Orleans on this gritty reality series. | M5: =IF(G5="","",YEAR(G5)) -> 2021 | N5: =IF(G5="","",MONTH(G5)) -> 9 | O5: =IFERROR(VLOOKUP(I5,Lists!$F$2:$G$16,2,FALSE()),"Not Rated") -> Adults | P5: =IFERROR(VALUE(LEFT(J5,FIND(" ",J5)-1)),"") -> 1 | Q5: =IFERROR(LEFT(F5,FIND(",",F5)-1),F5) -> Unknown | R5: ="|"&SUBSTITUTE(F5,", ","|")&"|" -> |Unknown| | S5: ="|"&SUBSTITUTE(K5,", ","|")&"|" -> |Docuseries|Reality TV| | T5: ="|"&SUBSTITUTE(D5,", ","|")&"|" -> |Unknown| | U5: ="|"&SUBSTITUTE(E5,", ","|")&"|" -> |Unknown|
A6: s5 | B6: TV Show | C6: Kota Factory | D6: Unknown | E6: Mayur More, Jitendra Kumar, Ranjan Raj, Alam Khan, Ahsaas Channa, Revathi Pillai, Urvi Singh, Arun Kumar | F6: India | G6: 44463 | H6: 2021 | I6: TV-MA | J6: 2 Seasons | K6: International TV Shows, Romantic TV Shows, TV Comedies | L6: In a city of coaching centers known to train India’s finest collegiate minds, an earnest but unexceptional student and his friends navigate campus life. | M6: =IF(G6="","",YEAR(G6)) -> 2021 | N6: =IF(G6="","",MONTH(G6)) -> 9 | O6: =IFERROR(VLOOKUP(I6,Lists!$F$2:$G$16,2,FALSE()),"Not Rated") -> Adults | P6: =IFERROR(VALUE(LEFT(J6,FIND(" ",J6)-1)),"") -> 2 | Q6: =IFERROR(LEFT(F6,FIND(",",F6)-1),F6) -> India | R6: ="|"&SUBSTITUTE(F6,", ","|")&"|" -> |India| | S6: ="|"&SUBSTITUTE(K6,", ","|")&"|" -> |International TV Shows|Romantic TV Shows|TV Comedies| | T6: ="|"&SUBSTITUTE(D6,", ","|")&"|" -> |Unknown| | U6: ="|"&SUBSTITUTE(E6,", ","|")&"|" -> |Mayur More|Jitendra Kumar|Ranjan Raj|Alam Khan|Ahsaas Channa|Revathi Pillai|Urvi Singh|Arun Kumar|
A7: s6 | B7: TV Show | C7: Midnight Mass | D7: Mike Flanagan | E7: Kate Siegel, Zach Gilford, Hamish Linklater, Henry Thomas, Kristin Lehman, Samantha Sloyan, Igby Rigney, Rahul Kohli, Annarah Cymone, Annabeth Gish, Alex Essoe, Rahul Abburi, Matt Biedel, Michael Trucco, Crystal Balint, Louis Oliver | F7: Unknown | G7: 44463 | H7: 2021 | I7: TV-MA | J7: 1 Season | K7: TV Dramas, TV Horror, TV Mysteries | L7: The arrival of a charismatic young priest brings glorious miracles, ominous mysteries and renewed religious fervor to a dying town desperate to believe. | M7: =IF(G7="","",YEAR(G7)) -> 2021 | N7: =IF(G7="","",MONTH(G7)) -> 9 | O7: =IFERROR(VLOOKUP(I7,Lists!$F$2:$G$16,2,FALSE()),"Not Rated") -> Adults | P7: =IFERROR(VALUE(LEFT(J7,FIND(" ",J7)-1)),"") -> 1 | Q7: =IFERROR(LEFT(F7,FIND(",",F7)-1),F7) -> Unknown | R7: ="|"&SUBSTITUTE(F7,", ","|")&"|" -> |Unknown| | S7: ="|"&SUBSTITUTE(K7,", ","|")&"|" -> |TV Dramas|TV Horror|TV Mysteries| | T7: ="|"&SUBSTITUTE(D7,", ","|")&"|" -> |Mike Flanagan| | U7: ="|"&SUBSTITUTE(E7,", ","|")&"|" -> |Kate Siegel|Zach Gilford|Hamish Linklater|Henry Thomas|Kristin Lehman|Samantha Sloyan|Igby Rigney|Rahul Kohli|Annarah Cymone|Annabeth Gish|Alex Essoe|Rahul Abburi|Matt Biedel|Michael Trucco|Crystal Balint|Louis Oliver|
A8: s7 | B8: Movie | C8: My Little Pony: A New Generation | D8: Robert Cullen, José Luis Ucha | E8: Vanessa Hudgens, Kimiko Glenn, James Marsden, Sofia Carson, Liza Koshy, Ken Jeong, Elizabeth Perkins, Jane Krakowski, Michael McKean, Phil LaMarr | F8: Unknown | G8: 44463 | H8: 2021 | I8: PG | J8: 91 min | K8: Children & Family Movies | L8: Equestria's divided. But a bright-eyed hero believes Earth Ponies, Pegasi and Unicorns should be pals — and, hoof to heart, she’s determined to prove it. | M8: =IF(G8="","",YEAR(G8)) -> 2021 | N8: =IF(G8="","",MONTH(G8)) -> 9 | O8: =IFERROR(VLOOKUP(I8,Lists!$F$2:$G$16,2,FALSE()),"Not Rated") -> Older Kids | P8: =IFERROR(VALUE(LEFT(J8,FIND(" ",J8)-1)),"") -> 91 | Q8: =IFERROR(LEFT(F8,FIND(",",F8)-1),F8) -> Unknown | R8: ="|"&SUBSTITUTE(F8,", ","|")&"|" -> |Unknown| | S8: ="|"&SUBSTITUTE(K8,", ","|")&"|" -> |Children & Family Movies| | T8: ="|"&SUBSTITUTE(D8,", ","|")&"|" -> |Robert Cullen|José Luis Ucha| | U8: ="|"&SUBSTITUTE(E8,", ","|")&"|" -> |Vanessa Hudgens|Kimiko Glenn|James Marsden|Sofia Carson|Liza Koshy|Ken Jeong|Elizabeth Perkins|Jane Krakowski|Michael McKean|Phil LaMarr|
A9: s8 | B9: Movie | C9: Sankofa | D9: Haile Gerima | E9: Kofi Ghanaba, Oyafunmike Ogunlano, Alexandra Duah, Nick Medley, Mutabaruka, Afemo Omilami, Reggie Carter, Mzuri | F9: United States, Ghana, Burkina Faso, United Kingdom, Germany, Ethiopia | G9: 44463 | H9: 1993 | I9: TV-MA | J9: 125 min | K9: Dramas, Independent Movies, International Movies | L9: On a photo shoot in Ghana, an American model slips back in time, becomes enslaved on a plantation and bears witness to the agony of her ancestral past. | M9: =IF(G9="","",YEAR(G9)) -> 2021 | N9: =IF(G9="","",MONTH(G9)) -> 9 | O9: =IFERROR(VLOOKUP(I9,Lists!$F$2:$G$16,2,FALSE()),"Not Rated") -> Adults | P9: =IFERROR(VALUE(LEFT(J9,FIND(" ",J9)-1)),"") -> 125 | Q9: =IFERROR(LEFT(F9,FIND(",",F9)-1),F9) -> United States | R9: ="|"&SUBSTITUTE(F9,", ","|")&"|" -> |United States|Ghana|Burkina Faso|United Kingdom|Germany|Ethiopia| | S9: ="|"&SUBSTITUTE(K9,", ","|")&"|" -> |Dramas|Independent Movies|International Movies| | T9: ="|"&SUBSTITUTE(D9,", ","|")&"|" -> |Haile Gerima| | U9: ="|"&SUBSTITUTE(E9,", ","|")&"|" -> |Kofi Ghanaba|Oyafunmike Ogunlano|Alexandra Duah|Nick Medley|Mutabaruka|Afemo Omilami|Reggie Carter|Mzuri|
A10: s9 | B10: TV Show | C10: The Great British Baking Show | D10: Andy Devonshire | E10: Mel Giedroyc, Sue Perkins, Mary Berry, Paul Hollywood | F10: United Kingdom | G10: 44463 | H10: 2021 | I10: TV-14 | J10: 9 Seasons | K10: British TV Shows, Reality TV | L10: A talented batch of amateur bakers face off in a 10-week competition, whipping up their best dishes in the hopes of being named the U.K.'s best. | M10: =IF(G10="","",YEAR(G10)) -> 2021 | N10: =IF(G10="","",MONTH(G10)) -> 9 | O10: =IFERROR(VLOOKUP(I10,Lists!$F$2:$G$16,2,FALSE()),"Not Rated") -> Teens | P10: =IFERROR(VALUE(LEFT(J10,FIND(" ",J10)-1)),"") -> 9 | Q10: =IFERROR(LEFT(F10,FIND(",",F10)-1),F10) -> United Kingdom | R10: ="|"&SUBSTITUTE(F10,", ","|")&"|" -> |United Kingdom| | S10: ="|"&SUBSTITUTE(K10,", ","|")&"|" -> |British TV Shows|Reality TV| | T10: ="|"&SUBSTITUTE(D10,", ","|")&"|" -> |Andy Devonshire| | U10: ="|"&SUBSTITUTE(E10,", ","|")&"|" -> |Mel Giedroyc|Sue Perkins|Mary Berry|Paul Hollywood|
A11: s10 | B11: Movie | C11: The Starling | D11: Theodore Melfi | E11: Melissa McCarthy, Chris O'Dowd, Kevin Kline, Timothy Olyphant, Daveed Diggs, Skyler Gisondo, Laura Harrier, Rosalind Chao, Kimberly Quinn, Loretta Devine, Ravi Kapoor | F11: United States | G11: 44463 | H11: 2021 | I11: PG-13 | J11: 104 min | K11: Comedies, Dramas | L11: A woman adjusting to life after a loss contends with a feisty bird that's taken over her garden — and a husband who's struggling to find a way forward. | M11: =IF(G11="","",YEAR(G11)) -> 2021 | N11: =IF(G11="","",MONTH(G11)) -> 9 | O11: =IFERROR(VLOOKUP(I11,Lists!$F$2:$G$16,2,FALSE()),"Not Rated") -> Teens | P11: =IFERROR(VALUE(LEFT(J11,FIND(" ",J11)-1)),"") -> 104 | Q11: =IFERROR(LEFT(F11,FIND(",",F11)-1),F11) -> United States | R11: ="|"&SUBSTITUTE(F11,", ","|")&"|" -> |United States| | S11: ="|"&SUBSTITUTE(K11,", ","|")&"|" -> |Comedies|Dramas| | T11: ="|"&SUBSTITUTE(D11,", ","|")&"|" -> |Theodore Melfi| | U11: ="|"&SUBSTITUTE(E11,", ","|")&"|" -> |Melissa McCarthy|Chris O'Dowd|Kevin Kline|Timothy Olyphant|Daveed Diggs|Skyler Gisondo|Laura Harrier|Rosalind Chao|Kimberly Quinn|Loretta Devine|Ravi Kapoor|
A12: s11 | B12: TV Show | C12: Vendetta: Truth, Lies and The Mafia | D12: Unknown | E12: Unknown | F12: Unknown | G12: 44463 | H12: 2021 | I12: TV-MA | J12: 1 Season | K12: Crime TV Shows, Docuseries, International TV Shows | L12: Sicily boasts a bold "Anti-Mafia" coalition. But what happens when those trying to bring down organized crime are accused of being criminals themselves? | M12: =IF(G12="","",YEAR(G12)) -> 2021 | N12: =IF(G12="","",MONTH(G12)) -> 9 | O12: =IFERROR(VLOOKUP(I12,Lists!$F$2:$G$16,2,FALSE()),"Not Rated") -> Adults | P12: =IFERROR(VALUE(LEFT(J12,FIND(" ",J12)-1)),"") -> 1 | Q12: =IFERROR(LEFT(F12,FIND(",",F12)-1),F12) -> Unknown | R12: ="|"&SUBSTITUTE(F12,", ","|")&"|" -> |Unknown| | S12: ="|"&SUBSTITUTE(K12,", ","|")&"|" -> |Crime TV Shows|Docuseries|International TV Shows| | T12: ="|"&SUBSTITUTE(D12,", ","|")&"|" -> |Unknown| | U12: ="|"&SUBSTITUTE(E12,", ","|")&"|" -> |Unknown|
A13: s12 | B13: TV Show | C13: Bangkok Breaking | D13: Kongkiat Komesiri | E13: Sukollawat Kanarot, Sushar Manaying, Pavarit Mongkolpisit, Sahajak Boonthanakit, Suthipongse Thatphithakkul, Bhasaworn Bawronkirati, Daweerit Chullasapya, Waratthaya Wongchayaporn, Kittiphoom Wongpentak, Abhicha Thanachanun, Nophand Boonyai, Kittipong Khamsat, Arisara Wongchalee, Jaytiya Naiwattanakul, Pantipa Arunwattanachai, Panupan Jantanawong, Kungtap Saelim, Phumphat Chartsuriyakiat, Issara Veranitinunt, Keerati Sivakuae, Panjai Sirisuwan, Supranee Charoenpol, Suda Chuenban, Visaka Banhansupavat, Pitchatorn Santinatornkul | F13: Unknown | G13: 44462 | H13: 2021 | I13: TV-MA | J13: 1 Season | K13: Crime TV Shows, International TV Shows, TV Action & Adventure | L13: Struggling to earn a living in Bangkok, a man joins an emergency rescue service and realizes he must unravel a citywide conspiracy. | M13: =IF(G13="","",YEAR(G13)) -> 2021 | N13: =IF(G13="","",MONTH(G13)) -> 9 | O13: =IFERROR(VLOOKUP(I13,Lists!$F$2:$G$16,2,FALSE()),"Not Rated") -> Adults | P13: =IFERROR(VALUE(LEFT(J13,FIND(" ",J13)-1)),"") -> 1 | Q13: =IFERROR(LEFT(F13,FIND(",",F13)-1),F13) -> Unknown | R13: ="|"&SUBSTITUTE(F13,", ","|")&"|" -> |Unknown| | S13: ="|"&SUBSTITUTE(K13,", ","|")&"|" -> |Crime TV Shows|International TV Shows|TV Action & Adventure| | T13: ="|"&SUBSTITUTE(D13,", ","|")&"|" -> |Kongkiat Komesiri| | U13: ="|"&SUBSTITUTE(E13,", ","|")&"|" -> |Sukollawat Kanarot|Sushar Manaying|Pavarit Mongkolpisit|Sahajak Boonthanakit|Suthipongse Thatphithakkul|Bhasaworn Bawronkirati|Daweerit Chullasapya|Waratthaya Wongchayaporn|Kittiphoom Wongpentak|Abhicha Thanachanun|Nophand Boonyai|Kittipong Khamsat|Arisara Wongchalee|Jaytiya Naiwattanakul|Pantipa Arunwattanachai|Panupan Jantanawong|Kungtap Saelim|Phumphat Chartsuriyakiat|Issara Veranitinunt|Keerati Sivakuae|Panjai Sirisuwan|Supranee Charoenpol|Suda Chuenban|Visaka Banhansupavat|Pitchatorn Santinatornkul|
... A6067: s6066 | B6067: Movie | C6067: A Wrinkle in Time | D6067: Ava DuVernay | E6067: Storm Reid, Oprah Winfrey, Reese Witherspoon, Mindy Kaling, Deric McCabe, Levi Miller, Chris Pine, Gugu Mbatha-Raw, Zach Galifianakis, Michael Peña, Bellamy Young, André Holland, Will McCormack, Rowan Blanchard, Daniel MacPherson | F6067: United States | G6067: 43368 | H6067: 2018 | I6067: PG | J6067: 110 min | K6067: Children & Family Movies | L6067: Years after their father disappears, Meg and her younger brother Charles Wallace cross galaxies on a quest to save him from the heart of darkness. | M6067: =IF(G6067="","",YEAR(G6067)) -> 2018 | N6067: =IF(G6067="","",MONTH(G6067)) -> 9 | O6067: =IFERROR(VLOOKUP(I6067,Lists!$F$2:$G$16,2,FALSE()),"Not Rated") -> Older Kids | P6067: =IFERROR(VALUE(LEFT(J6067,FIND(" ",J6067)-1)),"") -> 110 | Q6067: =IFERROR(LEFT(F6067,FIND(",",F6067)-1),F6067) -> United States | R6067: ="|"&SUBSTITUTE(F6067,", ","|")&"|" -> |United States| | S6067: ="|"&SUBSTITUTE(K6067,", ","|")&"|" -> |Children & Family Movies| | T6067: ="|"&SUBSTITUTE(D6067,", ","|")&"|" -> |Ava DuVernay| | U6067: ="|"&SUBSTITUTE(E6067,", ","|")&"|" -> |Storm Reid|Oprah Winfrey|Reese Witherspoon|Mindy Kaling|Deric McCabe|Levi Miller|Chris Pine|Gugu Mbatha-Raw|Zach Galifianakis|Michael Peña|Bellamy Young|André Holland|Will McCormack|Rowan Blanchard|Daniel MacPherson|
A6068: s6067 | B6068: TV Show | C6068: A Young Doctor's Notebook and Other Stories | D6068: Unknown | E6068: Daniel Radcliffe, Jon Hamm, Adam Godley, Christopher Godwin, Rosie Cavaliero, Vicki Pepperdine, Margaret Clunie, Tim Steed, Shaun Pye | F6068: United Kingdom | H6068: 2013 | I6068: TV-MA | J6068: 2 Seasons | K6068: British TV Shows, TV Comedies, TV Dramas | L6068: Set during the Russian Revolution, this comic miniseries is based on a doctor's memories of his early career working in an out-of-the-way village. | M6068: =IF(G6068="","",YEAR(G6068)) | N6068: =IF(G6068="","",MONTH(G6068)) | O6068: =IFERROR(VLOOKUP(I6068,Lists!$F$2:$G$16,2,FALSE()),"Not Rated") -> Adults | P6068: =IFERROR(VALUE(LEFT(J6068,FIND(" ",J6068)-1)),"") -> 2 | Q6068: =IFERROR(LEFT(F6068,FIND(",",F6068)-1),F6068) -> United Kingdom | R6068: ="|"&SUBSTITUTE(F6068,", ","|")&"|" -> |United Kingdom| | S6068: ="|"&SUBSTITUTE(K6068,", ","|")&"|" -> |British TV Shows|TV Comedies|TV Dramas| | T6068: ="|"&SUBSTITUTE(D6068,", ","|")&"|" -> |Unknown| | U6068: ="|"&SUBSTITUTE(E6068,", ","|")&"|" -> |Daniel Radcliffe|Jon Hamm|Adam Godley|Christopher Godwin|Rosie Cavaliero|Vicki Pepperdine|Margaret Clunie|Tim Steed|Shaun Pye|
A6069: s6068 | B6069: TV Show | C6069: A.D. Kingdom and Empire | D6069: Unknown | E6069: Juan Pablo Di Pace, Adam Levy, Chipo Chung, Babou Ceesay, Emmett Scanlan, Will Thorp, Richard Coyle, Vincent Regan, Greta Scacchi, James Callis, Joanne Whalley, Jodhi May, Chris Brazier, Fraser Ayres, Jóhannes Haukur Jóhannesson, Ken Bones, Kenneth Collard | F6069: United States | G6069: 43084 | H6069: 2015 | I6069: TV-14 | J6069: 1 Season | K6069: TV Dramas | L6069: In the wake of Jesus Christ's crucifixion, his apostles dedicate themselves to spreading his message, risking their freedom and their lives. | M6069: =IF(G6069="","",YEAR(G6069)) -> 2017 | N6069: =IF(G6069="","",MONTH(G6069)) -> 12 | O6069: =IFERROR(VLOOKUP(I6069,Lists!$F$2:$G$16,2,FALSE()),"Not Rated") -> Teens | P6069: =IFERROR(VALUE(LEFT(J6069,FIND(" ",J6069)-1)),"") -> 1 | Q6069: =IFERROR(LEFT(F6069,FIND(",",F6069)-1),F6069) -> United States | R6069: ="|"&SUBSTITUTE(F6069,", ","|")&"|" -> |United States| | S6069: ="|"&SUBSTITUTE(K6069,", ","|")&"|" -> |TV Dramas| | T6069: ="|"&SUBSTITUTE(D6069,", ","|")&"|" -> |Unknown| | U6069: ="|"&SUBSTITUTE(E6069,", ","|")&"|" -> |Juan Pablo Di Pace|Adam Levy|Chipo Chung|Babou Ceesay|Emmett Scanlan|Will Thorp|Richard Coyle|Vincent Regan|Greta Scacchi|James Callis|Joanne Whalley|Jodhi May|Chris Brazier|Fraser Ayres|Jóhannes Haukur Jóhannesson|Ken Bones|Kenneth Collard|
A6070: s6069 | B6070: Movie | C6070: A.M.I. | D6070: Rusty Nixon | E6070: Debs Howard, Philip Granger, Sam Robert Muik, Havana Guppy, Bonnie Hay, Veronica Hampson, Lori Triolo, Andrew Coghlan, Laura Mitchell, Elinet Louicius | F6070: Canada | G6070: 44105 | H6070: 2019 | I6070: TV-MA | J6070: 77 min | K6070: Horror Movies | L6070: After losing her mother, a teenage girl bonds with her phone’s artificial intelligence app, a relationship that soon takes a dark and violent turn. | M6070: =IF(G6070="","",YEAR(G6070)) -> 2020 | N6070: =IF(G6070="","",MONTH(G6070)) -> 10 | O6070: =IFERROR(VLOOKUP(I6070,Lists!$F$2:$G$16,2,FALSE()),"Not Rated") -> Adults | P6070: =IFERROR(VALUE(LEFT(J6070,FIND(" ",J6070)-1)),"") -> 77 | Q6070: =IFERROR(LEFT(F6070,FIND(",",F6070)-1),F6070) -> Canada | R6070: ="|"&SUBSTITUTE(F6070,", ","|")&"|" -> |Canada| | S6070: ="|"&SUBSTITUTE(K6070,", ","|")&"|" -> |Horror Movies| | T6070: ="|"&SUBSTITUTE(D6070,", ","|")&"|" -> |Rusty Nixon| | U6070: ="|"&SUBSTITUTE(E6070,", ","|")&"|" -> |Debs Howard|Philip Granger|Sam Robert Muik|Havana Guppy|Bonnie Hay|Veronica Hampson|Lori Triolo|Andrew Coghlan|Laura Mitchell|Elinet Louicius|
A6071: s6070 | B6071: Movie | C6071: A.X.L. | D6071: Oliver Daly | E6071: Alex Neustaedter, Becky G., Alex MacNicoll, Dominic Rains, Thomas Jane, Lou Taylor Pucci, Patricia De Leon, Niko Guardado, Ted McGinley, Marie-Françoise Theodore, Eric Etebari, Dorian Kingi | F6071: United States | G6071: 43544 | H6071: 2018 | I6071: PG | J6071: 99 min | K6071: Action & Adventure, Children & Family Movies, Independent Movies | L6071: Young motocross racer Miles Hill helps a top-secret robotic combat dog evade its ruthless creator and the military, who are in hot pursuit. | M6071: =IF(G6071="","",YEAR(G6071)) -> 2019 | N6071: =IF(G6071="","",MONTH(G6071)) -> 3 | O6071: =IFERROR(VLOOKUP(I6071,Lists!$F$2:$G$16,2,FALSE()),"Not Rated") -> Older Kids | P6071: =IFERROR(VALUE(LEFT(J6071,FIND(" ",J6071)-1)),"") -> 99 | Q6071: =IFERROR(LEFT(F6071,FIND(",",F6071)-1),F6071) -> United States | R6071: ="|"&SUBSTITUTE(F6071,", ","|")&"|" -> |United States| | S6071: ="|"&SUBSTITUTE(K6071,", ","|")&"|" -> |Action & Adventure|Children & Family Movies|Independent Movies| | T6071: ="|"&SUBSTITUTE(D6071,", ","|")&"|" -> |Oliver Daly| | U6071: ="|"&SUBSTITUTE(E6071,", ","|")&"|" -> |Alex Neustaedter|Becky G.|Alex MacNicoll|Dominic Rains|Thomas Jane|Lou Taylor Pucci|Patricia De Leon|Niko Guardado|Ted McGinley|Marie-Françoise Theodore|Eric Etebari|Dorian Kingi|
A6072: s6071 | B6072: Movie | C6072: Aşk Tesadüfleri Sever | D6072: Ömer Faruk Sorak | E6072: Mehmet Günsür, Belçim Bilgin, Ayda Aksel, Altan Erkekli, Sebnem Sönmez, Hüseyin Avni Danyal, Berna Konur, Ümit Bülent Dinçer | F6072: Turkey | G6072: 43194 | H6072: 2011 | I6072: TV-MA | J6072: 122 min | K6072: Dramas, International Movies, Romantic Movies | L6072: A series of coincidences brings two star-crossed lovers together, but fate pulls them apart until they encounter each other again in Istanbul. | M6072: =IF(G6072="","",YEAR(G6072)) -> 2018 | N6072: =IF(G6072="","",MONTH(G6072)) -> 4 | O6072: =IFERROR(VLOOKUP(I6072,Lists!$F$2:$G$16,2,FALSE()),"Not Rated") -> Adults | P6072: =IFERROR(VALUE(LEFT(J6072,FIND(" ",J6072)-1)),"") -> 122 | Q6072: =IFERROR(LEFT(F6072,FIND(",",F6072)-1),F6072) -> Turkey | R6072: ="|"&SUBSTITUTE(F6072,", ","|")&"|" -> |Turkey| | S6072: ="|"&SUBSTITUTE(K6072,", ","|")&"|" -> |Dramas|International Movies|Romantic Movies| | T6072: ="|"&SUBSTITUTE(D6072,", ","|")&"|" -> |Ömer Faruk Sorak| | U6072: ="|"&SUBSTITUTE(E6072,", ","|")&"|" -> |Mehmet Günsür|Belçim Bilgin|Ayda Aksel|Altan Erkekli|Sebnem Sönmez|Hüseyin Avni Danyal|Berna Konur|Ümit Bülent Dinçer|
A6073: s6072 | B6073: Movie | C6073: Aadu 2 | D6073: Midhun Manuel Thomas | E6073: Jayasurya, Vinayakan, Sunny Wayne, Vijay Babu, Saiju Kurup, Vineeth Mohan, Unni Rajan P. Dev, Dharmajan Bolgatty, Indrans | F6073: India | G6073: 43235 | H6073: 2017 | I6073: TV-MA | J6073: 150 min | K6073: Comedies, International Movies | L6073: When Shaji Pappan and his gang of goofy outlaws find themselves low on funds, they plan to once again win a hefty prize in a tug-of-war competition. | M6073: =IF(G6073="","",YEAR(G6073)) -> 2018 | N6073: =IF(G6073="","",MONTH(G6073)) -> 5 | O6073: =IFERROR(VLOOKUP(I6073,Lists!$F$2:$G$16,2,FALSE()),"Not Rated") -> Adults | P6073: =IFERROR(VALUE(LEFT(J6073,FIND(" ",J6073)-1)),"") -> 150 | Q6073: =IFERROR(LEFT(F6073,FIND(",",F6073)-1),F6073) -> India | R6073: ="|"&SUBSTITUTE(F6073,", ","|")&"|" -> |India| | S6073: ="|"&SUBSTITUTE(K6073,", ","|")&"|" -> |Comedies|International Movies| | T6073: ="|"&SUBSTITUTE(D6073,", ","|")&"|" -> |Midhun Manuel Thomas| | U6073: ="|"&SUBSTITUTE(E6073,", ","|")&"|" -> |Jayasurya|Vinayakan|Sunny Wayne|Vijay Babu|Saiju Kurup|Vineeth Mohan|Unni Rajan P. Dev|Dharmajan Bolgatty|Indrans|
A6074: s6073 | B6074: Movie | C6074: Aajcha Divas Majha | D6074: Chandrakant Kulkarni | E6074: Sachin Khedekar, Ashwini Bhave, Mahesh Manjrekar, Hrishikesh Joshi, Satish Alekar, Sunil Tawde, Pushkar Shrotri, Anand Ingle | F6074: India | G6074: 43101 | H6074: 2013 | I6074: TV-PG | J6074: 126 min | K6074: Comedies, Dramas, International Movies | L6074: A conscientious politician helps an elderly singer overcome the obstacles placed in his path a by a powerful bureaucracy. | M6074: =IF(G6074="","",YEAR(G6074)) -> 2018 | N6074: =IF(G6074="","",MONTH(G6074)) -> 1 | O6074: =IFERROR(VLOOKUP(I6074,Lists!$F$2:$G$16,2,FALSE()),"Not Rated") -> Older Kids | P6074: =IFERROR(VALUE(LEFT(J6074,FIND(" ",J6074)-1)),"") -> 126 | Q6074: =IFERROR(LEFT(F6074,FIND(",",F6074)-1),F6074) -> India | R6074: ="|"&SUBSTITUTE(F6074,", ","|")&"|" -> |India| | S6074: ="|"&SUBSTITUTE(K6074,", ","|")&"|" -> |Comedies|Dramas|International Movies| | T6074: ="|"&SUBSTITUTE(D6074,", ","|")&"|" -> |Chandrakant Kulkarni| | U6074: ="|"&SUBSTITUTE(E6074,", ","|")&"|" -> |Sachin Khedekar|Ashwini Bhave|Mahesh Manjrekar|Hrishikesh Joshi|Satish Alekar|Sunil Tawde|Pushkar Shrotri|Anand Ingle|
A6075: s6074 | B6075: Movie | C6075: Aarakshan | D6075: Prakash Jha | E6075: Amitabh Bachchan, Saif Ali Khan, Manoj Bajpayee, Deepika Padukone, Prateik, Tanvi Azmi, Saurabh Shukla, Darshan Jariwala, Yashpal Sharma, Mukesh Tiwari | F6075: India | G6075: 43830 | H6075: 2011 | I6075: TV-14 | J6075: 164 min | K6075: Dramas, International Movies | L6075: The decision by India's supreme court to establish caste-based reservations for jobs in education causes conflict between a teacher and his mentor. | M6075: =IF(G6075="","",YEAR(G6075)) -> 2019 | N6075: =IF(G6075="","",MONTH(G6075)) -> 12 | O6075: =IFERROR(VLOOKUP(I6075,Lists!$F$2:$G$16,2,FALSE()),"Not Rated") -> Teens | P6075: =IFERROR(VALUE(LEFT(J6075,FIND(" ",J6075)-1)),"") -> 164 | Q6075: =IFERROR(LEFT(F6075,FIND(",",F6075)-1),F6075) -> India | R6075: ="|"&SUBSTITUTE(F6075,", ","|")&"|" -> |India| | S6075: ="|"&SUBSTITUTE(K6075,", ","|")&"|" -> |Dramas|International Movies| | T6075: ="|"&SUBSTITUTE(D6075,", ","|")&"|" -> |Prakash Jha| | U6075: ="|"&SUBSTITUTE(E6075,", ","|")&"|" -> |Amitabh Bachchan|Saif Ali Khan|Manoj Bajpayee|Deepika Padukone|Prateik|Tanvi Azmi|Saurabh Shukla|Darshan Jariwala|Yashpal Sharma|Mukesh Tiwari|
A6076: s6075 | B6076: Movie | C6076: Aashayein | D6076: Nagesh Kukunoor | E6076: John Abraham, Sonal Sehgal, Prateeksha Lonkar, Girish Karnad, Farida Jalal, Ashwin Chitale, Anaitha Nair, Vikram Inamdar, Vipin Bhali, Poonam Chitale, Nagesh Kukunoor | F6076: India | G6076: 43030 | H6076: 2010 | I6076: TV-14 | J6076: 115 min | K6076: Dramas, International Movies | L6076: When he learns he has terminal cancer, a cynical gambler and chronic smoker ditches his fiancée, snubs doctors and checks into a nursing home to die. | M6076: =IF(G6076="","",YEAR(G6076)) -> 2017 | N6076: =IF(G6076="","",MONTH(G6076)) -> 10 | O6076: =IFERROR(VLOOKUP(I6076,Lists!$F$2:$G$16,2,FALSE()),"Not Rated") -> Teens | P6076: =IFERROR(VALUE(LEFT(J6076,FIND(" ",J6076)-1)),"") -> 115 | Q6076: =IFERROR(LEFT(F6076,FIND(",",F6076)-1),F6076) -> India | R6076: ="|"&SUBSTITUTE(F6076,", ","|")&"|" -> |India| | S6076: ="|"&SUBSTITUTE(K6076,", ","|")&"|" -> |Dramas|International Movies| | T6076: ="|"&SUBSTITUTE(D6076,", ","|")&"|" -> |Nagesh Kukunoor| | U6076: ="|"&SUBSTITUTE(E6076,", ","|")&"|" -> |John Abraham|Sonal Sehgal|Prateeksha Lonkar|Girish Karnad|Farida Jalal|Ashwin Chitale|Anaitha Nair|Vikram Inamdar|Vipin Bhali|Poonam Chitale|Nagesh Kukunoor|
A6077: s6076 | B6077: Movie | C6077: Aata Pita | D6077: Uttung Shelar | E6077: Sanjay Narvekar, Bharat Jadhav, Satish Phulekar, Ashwini Apte | F6077: India | G6077: 43101 | H6077: 2010 | I6077: TV-14 | J6077: 133 min | K6077: Comedies, Dramas, International Movies | L6077: A municipal clerk with literary ambitions stalks a loan recovery officer on whom he has decided to base his story's central character. | M6077: =IF(G6077="","",YEAR(G6077)) -> 2018 | N6077: =IF(G6077="","",MONTH(G6077)) -> 1 | O6077: =IFERROR(VLOOKUP(I6077,Lists!$F$2:$G$16,2,FALSE()),"Not Rated") -> Teens | P6077: =IFERROR(VALUE(LEFT(J6077,FIND(" ",J6077)-1)),"") -> 133 | Q6077: =IFERROR(LEFT(F6077,FIND(",",F6077)-1),F6077) -> India | R6077: ="|"&SUBSTITUTE(F6077,", ","|")&"|" -> |India| | S6077: ="|"&SUBSTITUTE(K6077,", ","|")&"|" -> |Comedies|Dramas|International Movies| | T6077: ="|"&SUBSTITUTE(D6077,", ","|")&"|" -> |Uttung Shelar| | U6077: ="|"&SUBSTITUTE(E6077,", ","|")&"|" -> |Sanjay Narvekar|Bharat Jadhav|Satish Phulekar|Ashwini Apte|
A6078: s6077 | B6078: Movie | C6078: Abby Sen | D6078: Atanu Ghosh | E6078: Abir Chatterjee, Raima Sen, Arunima Ghosh, Priyanka Sarkar, Sujan Mukherjee, Kanchan Mullick, Biswanath Basu, Bhaswar Chatterjee, Swagata Basu, Tuhin Mitra, Paran Banerjee, Kharaj Mukherjee, Chiranjit | F6078: India | G6078: 42856 | H6078: 2015 | I6078: TV-PG | J6078: 127 min | K6078: Comedies, Dramas, International Movies | L6078: After losing his seventh job in a row, a TV producer and sci-fi buff travels back in time to 1980, where his employment prospects improve. | M6078: =IF(G6078="","",YEAR(G6078)) -> 2017 | N6078: =IF(G6078="","",MONTH(G6078)) -> 5 | O6078: =IFERROR(VLOOKUP(I6078,Lists!$F$2:$G$16,2,FALSE()),"Not Rated") -> Older Kids | P6078: =IFERROR(VALUE(LEFT(J6078,FIND(" ",J6078)-1)),"") -> 127 | Q6078: =IFERROR(LEFT(F6078,FIND(",",F6078)-1),F6078) -> India | R6078: ="|"&SUBSTITUTE(F6078,", ","|")&"|" -> |India| | S6078: ="|"&SUBSTITUTE(K6078,", ","|")&"|" -> |Comedies|Dramas|International Movies| | T6078: ="|"&SUBSTITUTE(D6078,", ","|")&"|" -> |Atanu Ghosh| | U6078: ="|"&SUBSTITUTE(E6078,", ","|")&"|" -> |Abir Chatterjee|Raima Sen|Arunima Ghosh|Priyanka Sarkar|Sujan Mukherjee|Kanchan Mullick|Biswanath Basu|Bhaswar Chatterjee|Swagata Basu|Tuhin Mitra|Paran Banerjee|Kharaj Mukherjee|Chiranjit|
A6079: s6078 | B6079: Movie | C6079: Abdo Mota | D6079: Unknown | E6079: Mohamed Ramadan | F6079: Egypt | G6079: 43574 | H6079: 2012 | I6079: TV-MA | J6079: 100 min | K6079: Action & Adventure, Dramas, International Movies | L6079: Following the mysterious death of his parents, a young man finds himself enmeshed in the dark world of drugs and crime. | M6079: =IF(G6079="","",YEAR(G6079)) -> 2019 | N6079: =IF(G6079="","",MONTH(G6079)) -> 4 | O6079: =IFERROR(VLOOKUP(I6079,Lists!$F$2:$G$16,2,FALSE()),"Not Rated") -> Adults | P6079: =IFERROR(VALUE(LEFT(J6079,FIND(" ",J6079)-1)),"") -> 100 | Q6079: =IFERROR(LEFT(F6079,FIND(",",F6079)-1),F6079) -> Egypt | R6079: ="|"&SUBSTITUTE(F6079,", ","|")&"|" -> |Egypt| | S6079: ="|"&SUBSTITUTE(K6079,", ","|")&"|" -> |Action & Adventure|Dramas|International Movies| | T6079: ="|"&SUBSTITUTE(D6079,", ","|")&"|" -> |Unknown| | U6079: ="|"&SUBSTITUTE(E6079,", ","|")&"|" -> |Mohamed Ramadan|
A6080: s6079 | B6080: Movie | C6080: Abhinetri | D6080: A. L. Vijay | E6080: Tamannaah Bhatia, Prabhu Deva, Sonu Sood, Sapthagiri, Murli Sharma, R.V. Udhaykumar, Joy Mathew, Hema | F6080: India | G6080: 43221 | H6080: 2016 | I6080: TV-14 | J6080: 131 min | K6080: Comedies, International Movies, Sci-Fi & Fantasy | L6080: Due to family pressure, a corporate man reluctantly marries a woman from the village, but in their new home, she abruptly assumes a different persona. | M6080: =IF(G6080="","",YEAR(G6080)) -> 2018 | N6080: =IF(G6080="","",MONTH(G6080)) -> 5 | O6080: =IFERROR(VLOOKUP(I6080,Lists!$F$2:$G$16,2,FALSE()),"Not Rated") -> Teens | P6080: =IFERROR(VALUE(LEFT(J6080,FIND(" ",J6080)-1)),"") -> 131 | Q6080: =IFERROR(LEFT(F6080,FIND(",",F6080)-1),F6080) -> India | R6080: ="|"&SUBSTITUTE(F6080,", ","|")&"|" -> |India| | S6080: ="|"&SUBSTITUTE(K6080,", ","|")&"|" -> |Comedies|International Movies|Sci-Fi & Fantasy| | T6080: ="|"&SUBSTITUTE(D6080,", ","|")&"|" -> |A. L. Vijay| | U6080: ="|"&SUBSTITUTE(E6080,", ","|")&"|" -> |Tamannaah Bhatia|Prabhu Deva|Sonu Sood|Sapthagiri|Murli Sharma|R.V. Udhaykumar|Joy Mathew|Hema|
... A6175: s6174 | B6175: Movie | C6175: Antariksha Ke Rakhwale | D6175: Anirban Majumder | E6175: Sonal Kaushal, Rupa Bhimani, Julie Tejwani, Sabina Malik, Jigna Bharadhwaj, Rajesh Kawa | F6175: Unknown | G6175: 43634 | H6175: 2018 | I6175: TV-Y7 | J6175: 65 min | K6175: Children & Family Movies | L6175: Space villains have abducted all the superheroes! It’s up to Bheem and his trusty team to save the others. | M6175: =IF(G6175="","",YEAR(G6175)) -> 2019 | N6175: =IF(G6175="","",MONTH(G6175)) -> 6 | O6175: =IFERROR(VLOOKUP(I6175,Lists!$F$2:$G$16,2,FALSE()),"Not Rated") -> Kids | P6175: =IFERROR(VALUE(LEFT(J6175,FIND(" ",J6175)-1)),"") -> 65 | Q6175: =IFERROR(LEFT(F6175,FIND(",",F6175)-1),F6175) -> Unknown | R6175: ="|"&SUBSTITUTE(F6175,", ","|")&"|" -> |Unknown| | S6175: ="|"&SUBSTITUTE(K6175,", ","|")&"|" -> |Children & Family Movies| | T6175: ="|"&SUBSTITUTE(D6175,", ","|")&"|" -> |Anirban Majumder| | U6175: ="|"&SUBSTITUTE(E6175,", ","|")&"|" -> |Sonal Kaushal|Rupa Bhimani|Julie Tejwani|Sabina Malik|Jigna Bharadhwaj|Rajesh Kawa|
A6176: s6175 | B6176: TV Show | C6176: Anthony Bourdain: Parts Unknown | D6176: Unknown | E6176: Anthony Bourdain | F6176: United States | H6176: 2018 | I6176: TV-PG | J6176: 5 Seasons | K6176: Docuseries | L6176: This CNN original series has chef Anthony Bourdain traveling to extraordinary locations around the globe to sample a variety of local cuisines. | M6176: =IF(G6176="","",YEAR(G6176)) | N6176: =IF(G6176="","",MONTH(G6176)) | O6176: =IFERROR(VLOOKUP(I6176,Lists!$F$2:$G$16,2,FALSE()),"Not Rated") -> Older Kids | P6176: =IFERROR(VALUE(LEFT(J6176,FIND(" ",J6176)-1)),"") -> 5 | Q6176: =IFERROR(LEFT(F6176,FIND(",",F6176)-1),F6176) -> United States | R6176: ="|"&SUBSTITUTE(F6176,", ","|")&"|" -> |United States| | S6176: ="|"&SUBSTITUTE(K6176,", ","|")&"|" -> |Docuseries| | T6176: ="|"&SUBSTITUTE(D6176,", ","|")&"|" -> |Unknown| | U6176: ="|"&SUBSTITUTE(E6176,", ","|")&"|" -> |Anthony Bourdain|
A6177: s6176 | B6177: Movie | C6177: Antidote | D6177: Ken Barbet | E6177: Randy Couture, Chuck Zito, Wil Traval, Celeste Thornton, Rafael De La Fuente, Alyona Chekhova, Natali Yura, Thom Rivera | F6177: United States | G6177: 43569 | H6177: 2018 | I6177: TV-MA | J6177: 90 min | K6177: Action & Adventure, Horror Movies | L6177: A tough-as-nails treasure hunter protects a humanitarian doctor as she tries to cure a supernatural disease caused by a mysterious witch. | M6177: =IF(G6177="","",YEAR(G6177)) -> 2019 | N6177: =IF(G6177="","",MONTH(G6177)) -> 4 | O6177: =IFERROR(VLOOKUP(I6177,Lists!$F$2:$G$16,2,FALSE()),"Not Rated") -> Adults | P6177: =IFERROR(VALUE(LEFT(J6177,FIND(" ",J6177)-1)),"") -> 90 | Q6177: =IFERROR(LEFT(F6177,FIND(",",F6177)-1),F6177) -> United States | R6177: ="|"&SUBSTITUTE(F6177,", ","|")&"|" -> |United States| | S6177: ="|"&SUBSTITUTE(K6177,", ","|")&"|" -> |Action & Adventure|Horror Movies| | T6177: ="|"&SUBSTITUTE(D6177,", ","|")&"|" -> |Ken Barbet| | U6177: ="|"&SUBSTITUTE(E6177,", ","|")&"|" -> |Randy Couture|Chuck Zito|Wil Traval|Celeste Thornton|Rafael De La Fuente|Alyona Chekhova|Natali Yura|Thom Rivera|
A6178: s6177 | B6178: Movie | C6178: Anwar | D6178: Manish Jha | E6178: Siddharth Koirala, Nauheed Cyrusi, Manisha Koirala, Rajpal Yadav, Yashpal Sharma, Vijay Raaz, Hiten Tejwani, Sudhir Pandey, Sanjay Mishra, Lalit Tiwari | F6178: India | G6178: 43830 | H6178: 2007 | I6178: TV-14 | J6178: 134 min | K6178: Dramas, Independent Movies, International Movies | L6178: Seeking refuge in a Hindu temple after the tragic death of the girl he loved, a Muslim youth is caught by the police, who mistake him for an enemy. | M6178: =IF(G6178="","",YEAR(G6178)) -> 2019 | N6178: =IF(G6178="","",MONTH(G6178)) -> 12 | O6178: =IFERROR(VLOOKUP(I6178,Lists!$F$2:$G$16,2,FALSE()),"Not Rated") -> Teens | P6178: =IFERROR(VALUE(LEFT(J6178,FIND(" ",J6178)-1)),"") -> 134 | Q6178: =IFERROR(LEFT(F6178,FIND(",",F6178)-1),F6178) -> India | R6178: ="|"&SUBSTITUTE(F6178,", ","|")&"|" -> |India| | S6178: ="|"&SUBSTITUTE(K6178,", ","|")&"|" -> |Dramas|Independent Movies|International Movies| | T6178: ="|"&SUBSTITUTE(D6178,", ","|")&"|" -> |Manish Jha| | U6178: ="|"&SUBSTITUTE(E6178,", ","|")&"|" -> |Siddharth Koirala|Nauheed Cyrusi|Manisha Koirala|Rajpal Yadav|Yashpal Sharma|Vijay Raaz|Hiten Tejwani|Sudhir Pandey|Sanjay Mishra|Lalit Tiwari|
A6179: s6178 | B6179: TV Show | C6179: 忍者ハットリくん | D6179: Unknown | E6179: Unknown | F6179: Japan | G6179: 43457 | H6179: 2012 | I6179: TV-Y7 | J6179: 2 Seasons | K6179: Anime Series, Kids' TV | L6179: Hailing from the mountains of Iga, Kanzo Hattori moves in with elementary school student Kenichi Mitsuba and his family to hone his skills as a ninja. | M6179: =IF(G6179="","",YEAR(G6179)) -> 2018 | N6179: =IF(G6179="","",MONTH(G6179)) -> 12 | O6179: =IFERROR(VLOOKUP(I6179,Lists!$F$2:$G$16,2,FALSE()),"Not Rated") -> Kids | P6179: =IFERROR(VALUE(LEFT(J6179,FIND(" ",J6179)-1)),"") -> 2 | Q6179: =IFERROR(LEFT(F6179,FIND(",",F6179)-1),F6179) -> Japan | R6179: ="|"&SUBSTITUTE(F6179,", ","|")&"|" -> |Japan| | S6179: ="|"&SUBSTITUTE(K6179,", ","|")&"|" -> |Anime Series|Kids' TV| | T6179: ="|"&SUBSTITUTE(D6179,", ","|")&"|" -> |Unknown| | U6179: ="|"&SUBSTITUTE(E6179,", ","|")&"|" -> |Unknown|
A6180: s6179 | B6180: Movie | C6180: Apache Warrior | D6180: David Salzberg, Christian Tureaud | E6180: Unknown | F6180: United States | G6180: 43770 | H6180: 2017 | I6180: TV-MA | J6180: 89 min | K6180: Documentaries | L6180: Recovered cockpit footage and telling interviews reveal the true stories of US fighter pilots in one of the largest combat strikes in history. | M6180: =IF(G6180="","",YEAR(G6180)) -> 2019 | N6180: =IF(G6180="","",MONTH(G6180)) -> 11 | O6180: =IFERROR(VLOOKUP(I6180,Lists!$F$2:$G$16,2,FALSE()),"Not Rated") -> Adults | P6180: =IFERROR(VALUE(LEFT(J6180,FIND(" ",J6180)-1)),"") -> 89 | Q6180: =IFERROR(LEFT(F6180,FIND(",",F6180)-1),F6180) -> United States | R6180: ="|"&SUBSTITUTE(F6180,", ","|")&"|" -> |United States| | S6180: ="|"&SUBSTITUTE(K6180,", ","|")&"|" -> |Documentaries| | T6180: ="|"&SUBSTITUTE(D6180,", ","|")&"|" -> |David Salzberg|Christian Tureaud| | U6180: ="|"&SUBSTITUTE(E6180,", ","|")&"|" -> |Unknown|
A6181: s6180 | B6181: Movie | C6181: APEX: The Story of the Hypercar | D6181: J.F. Musial, Josh Vietze | E6181: Zachary Levi | F6181: United States | G6181: 42583 | H6181: 2016 | I6181: NR | J6181: 86 min | K6181: Documentaries | L6181: A visionary carmaker introduces his fuel-efficient, high-performance hypercar to a market filled with big-name competitors like Ferrari and Porsche. | M6181: =IF(G6181="","",YEAR(G6181)) -> 2016 | N6181: =IF(G6181="","",MONTH(G6181)) -> 8 | O6181: =IFERROR(VLOOKUP(I6181,Lists!$F$2:$G$16,2,FALSE()),"Not Rated") -> Not Rated | P6181: =IFERROR(VALUE(LEFT(J6181,FIND(" ",J6181)-1)),"") -> 86 | Q6181: =IFERROR(LEFT(F6181,FIND(",",F6181)-1),F6181) -> United States | R6181: ="|"&SUBSTITUTE(F6181,", ","|")&"|" -> |United States| | S6181: ="|"&SUBSTITUTE(K6181,", ","|")&"|" -> |Documentaries| | T6181: ="|"&SUBSTITUTE(D6181,", ","|")&"|" -> |J.F. Musial|Josh Vietze| | U6181: ="|"&SUBSTITUTE(E6181,", ","|")&"|" -> |Zachary Levi|
A6182: s6181 | B6182: Movie | C6182: Apollo 18 | D6182: Gonzalo López-Gallego | E6182: Warren Christie, Lloyd Owen, Ryan Robbins, Michael Kopsa, Andrew Airlie | F6182: United States, Canada | G6182: 43533 | H6182: 2011 | I6182: PG-13 | J6182: 87 min | K6182: Horror Movies, Sci-Fi & Fantasy, Thrillers | L6182: This sci-fi thriller suggests that Apollo 17, despite official statements to the contrary, wasn't NASA's last manned mission to the moon. | M6182: =IF(G6182="","",YEAR(G6182)) -> 2019 | N6182: =IF(G6182="","",MONTH(G6182)) -> 3 | O6182: =IFERROR(VLOOKUP(I6182,Lists!$F$2:$G$16,2,FALSE()),"Not Rated") -> Teens | P6182: =IFERROR(VALUE(LEFT(J6182,FIND(" ",J6182)-1)),"") -> 87 | Q6182: =IFERROR(LEFT(F6182,FIND(",",F6182)-1),F6182) -> United States | R6182: ="|"&SUBSTITUTE(F6182,", ","|")&"|" -> |United States|Canada| | S6182: ="|"&SUBSTITUTE(K6182,", ","|")&"|" -> |Horror Movies|Sci-Fi & Fantasy|Thrillers| | T6182: ="|"&SUBSTITUTE(D6182,", ","|")&"|" -> |Gonzalo López-Gallego| | U6182: ="|"&SUBSTITUTE(E6182,", ","|")&"|" -> |Warren Christie|Lloyd Owen|Ryan Robbins|Michael Kopsa|Andrew Airlie|
A6183: s6182 | B6183: Movie | C6183: April and the Extraordinary World | D6183: Christian Desmares, Franck Ekinci | E6183: Angela Galuppo, Paul Giamatti, Susan Sarandon, Tony Hale, J.K. Simmons, Tony Robinow, Mark Camacho, Tod Fennell, Carlos Alazraqui, Kari Wahlgren | F6183: France, Canada, Belgium | G6183: 43009 | H6183: 2015 | I6183: PG | J6183: 107 min | K6183: Action & Adventure, Comedies, International Movies | L6183: After the world's top scientists disappear, orphaned April secretly forges ahead with a family experiment and gets tangled up in a vast conspiracy. | M6183: =IF(G6183="","",YEAR(G6183)) -> 2017 | N6183: =IF(G6183="","",MONTH(G6183)) -> 10 | O6183: =IFERROR(VLOOKUP(I6183,Lists!$F$2:$G$16,2,FALSE()),"Not Rated") -> Older Kids | P6183: =IFERROR(VALUE(LEFT(J6183,FIND(" ",J6183)-1)),"") -> 107 | Q6183: =IFERROR(LEFT(F6183,FIND(",",F6183)-1),F6183) -> France | R6183: ="|"&SUBSTITUTE(F6183,", ","|")&"|" -> |France|Canada|Belgium| | S6183: ="|"&SUBSTITUTE(K6183,", ","|")&"|" -> |Action & Adventure|Comedies|International Movies| | T6183: ="|"&SUBSTITUTE(D6183,", ","|")&"|" -> |Christian Desmares|Franck Ekinci| | U6183: ="|"&SUBSTITUTE(E6183,", ","|")&"|" -> |Angela Galuppo|Paul Giamatti|Susan Sarandon|Tony Hale|J.K. Simmons|Tony Robinow|Mark Camacho|Tod Fennell|Carlos Alazraqui|Kari Wahlgren|
A6184: s6183 | B6184: Movie | C6184: Aram, Aram | D6184: Christopher Chambers | E6184: John Roohinian, Levon Sharafyan, Sevak Hakoyan, David Villada, Mike Ghader, Razmik Mansuryan, Lorita Meg, Amy Sanders, Alla Tumanian | F6184: United States | G6184: 42781 | H6184: 2015 | I6184: TV-14 | J6184: 79 min | K6184: Dramas, Independent Movies | L6184: Newly orphaned Aram leaves Beirut to live with his grandfather in Los Angeles, and overwhelmed by culture shock, he falls prey to an Armenian gang. | M6184: =IF(G6184="","",YEAR(G6184)) -> 2017 | N6184: =IF(G6184="","",MONTH(G6184)) -> 2 | O6184: =IFERROR(VLOOKUP(I6184,Lists!$F$2:$G$16,2,FALSE()),"Not Rated") -> Teens | P6184: =IFERROR(VALUE(LEFT(J6184,FIND(" ",J6184)-1)),"") -> 79 | Q6184: =IFERROR(LEFT(F6184,FIND(",",F6184)-1),F6184) -> United States | R6184: ="|"&SUBSTITUTE(F6184,", ","|")&"|" -> |United States| | S6184: ="|"&SUBSTITUTE(K6184,", ","|")&"|" -> |Dramas|Independent Movies| | T6184: ="|"&SUBSTITUTE(D6184,", ","|")&"|" -> |Christopher Chambers| | U6184: ="|"&SUBSTITUTE(E6184,", ","|")&"|" -> |John Roohinian|Levon Sharafyan|Sevak Hakoyan|David Villada|Mike Ghader|Razmik Mansuryan|Lorita Meg|Amy Sanders|Alla Tumanian|
A6185: s6184 | B6185: Movie | C6185: Are We Done Yet? | D6185: Khaled El Halafawy | E6185: Ahmed Eid, Ayten Amer, Ahmed Fouad Selim, Mohsen Mansour | F6185: Egypt | G6185: 43678 | H6185: 2018 | I6185: TV-14 | J6185: 87 min | K6185: Comedies, Dramas, International Movies | L6185: When authorities arrest his young son, a taxi driver must convince the courts and rabid media that he's not the criminal they seek. | M6185: =IF(G6185="","",YEAR(G6185)) -> 2019 | N6185: =IF(G6185="","",MONTH(G6185)) -> 8 | O6185: =IFERROR(VLOOKUP(I6185,Lists!$F$2:$G$16,2,FALSE()),"Not Rated") -> Teens | P6185: =IFERROR(VALUE(LEFT(J6185,FIND(" ",J6185)-1)),"") -> 87 | Q6185: =IFERROR(LEFT(F6185,FIND(",",F6185)-1),F6185) -> Egypt | R6185: ="|"&SUBSTITUTE(F6185,", ","|")&"|" -> |Egypt| | S6185: ="|"&SUBSTITUTE(K6185,", ","|")&"|" -> |Comedies|Dramas|International Movies| | T6185: ="|"&SUBSTITUTE(D6185,", ","|")&"|" -> |Khaled El Halafawy| | U6185: ="|"&SUBSTITUTE(E6185,", ","|")&"|" -> |Ahmed Eid|Ayten Amer|Ahmed Fouad Selim|Mohsen Mansour|
A6186: s6185 | B6186: Movie | C6186: Arisan 2 | D6186: Nia Dinata | E6186: Surya Saputra, Cut Mini Theo, Tora Sudiro | F6186: Indonesia | G6186: 43358 | H6186: 2011 | I6186: TV-14 | J6186: 113 min | K6186: Comedies, Dramas, International Movies | L6186: A group of friends reunites for a vacation amid nature, where they laugh about their shared history and bond over difficult truths. | M6186: =IF(G6186="","",YEAR(G6186)) -> 2018 | N6186: =IF(G6186="","",MONTH(G6186)) -> 9 | O6186: =IFERROR(VLOOKUP(I6186,Lists!$F$2:$G$16,2,FALSE()),"Not Rated") -> Teens | P6186: =IFERROR(VALUE(LEFT(J6186,FIND(" ",J6186)-1)),"") -> 113 | Q6186: =IFERROR(LEFT(F6186,FIND(",",F6186)-1),F6186) -> Indonesia | R6186: ="|"&SUBSTITUTE(F6186,", ","|")&"|" -> |Indonesia| | S6186: ="|"&SUBSTITUTE(K6186,", ","|")&"|" -> |Comedies|Dramas|International Movies| | T6186: ="|"&SUBSTITUTE(D6186,", ","|")&"|" -> |Nia Dinata| | U6186: ="|"&SUBSTITUTE(E6186,", ","|")&"|" -> |Surya Saputra|Cut Mini Theo|Tora Sudiro|
A6187: s6186 | B6187: Movie | C6187: Arthur | D6187: Jason Winer | E6187: Russell Brand, Helen Mirren, Greta Gerwig, Jennifer Garner, Geraldine James, Luis Guzmán, Nick Nolte, Christina Jacquelyn Calph, Murphy Guyer, José Ramón Rosario | F6187: United States | G6187: 43556 | H6187: 2011 | I6187: PG-13 | J6187: 110 min | K6187: Comedies, Romantic Movies | L6187: Russell Brand stars in this remake as a philanderer who must decide whether to give up an inheritance of millions for the sake of romance. | M6187: =IF(G6187="","",YEAR(G6187)) -> 2019 | N6187: =IF(G6187="","",MONTH(G6187)) -> 4 | O6187: =IFERROR(VLOOKUP(I6187,Lists!$F$2:$G$16,2,FALSE()),"Not Rated") -> Teens | P6187: =IFERROR(VALUE(LEFT(J6187,FIND(" ",J6187)-1)),"") -> 110 | Q6187: =IFERROR(LEFT(F6187,FIND(",",F6187)-1),F6187) -> United States | R6187: ="|"&SUBSTITUTE(F6187,", ","|")&"|" -> |United States| | S6187: ="|"&SUBSTITUTE(K6187,", ","|")&"|" -> |Comedies|Romantic Movies| | T6187: ="|"&SUBSTITUTE(D6187,", ","|")&"|" -> |Jason Winer| | U6187: ="|"&SUBSTITUTE(E6187,", ","|")&"|" -> |Russell Brand|Helen Mirren|Greta Gerwig|Jennifer Garner|Geraldine James|Luis Guzmán|Nick Nolte|Christina Jacquelyn Calph|Murphy Guyer|José Ramón Rosario|
...

Sheet Lists
A1: Type | B1: Rating Group | C1: Country | D1: Genre | E1: Year | F1: Rating | G1: Rating → Group
A2: All | B2: All | C2: All | D2: All | E2: 1925 | F2: TV-MA | G2: Adults
A3: Movie | B3: Adults | C3: United States | D3: International Movies | E3: 1926 | F3: TV-14 | G3: Teens
A4: TV Show | B4: Teens | C4: India | D4: Dramas | E4: 1927 | F4: TV-PG | G4: Older Kids
B5: Older Kids | C5: Unknown | D5: Comedies | E5: 1928 | F5: R | G5: Adults
B6: Kids | C6: United Kingdom | D6: International TV Shows | E6: 1929 | F6: PG-13 | G6: Teens
B7: Not Rated | C7: Canada | D7: Documentaries | E7: 1930 | F7: TV-Y7 | G7: Kids
C8: France | D8: Action & Adventure | E8: 1931 | F8: TV-Y | G8: Kids
C9: Japan | D9: TV Dramas | E9: 1932 | F9: PG | G9: Older Kids
C10: Spain | D10: Independent Movies | E10: 1933 | F10: TV-G | G10: Kids
C11: South Korea | D11: Children & Family Movies | E11: 1934 | F11: NR | G11: Not Rated
C12: Germany | D12: Romantic Movies | E12: 1935 | F12: G | G12: Kids
C13: Mexico | D13: TV Comedies | E13: 1936 | F13: Not Rated | G13: Not Rated
C14: China | D14: Thrillers | E14: 1937 | F14: TV-Y7-FV | G14: Kids
